<mujoco model="partnet_985eb4a8f9914873738e43095496b061">
  <compiler angle="radian" meshdir="blender_meshes/"/>

  <asset>
    <mesh name="link_0" file="link_0.obj"/>
    <mesh name="link_1" file="link_1.obj"/>
  </asset>

  <worldbody>
    <geom name="link_1_collision" pos="0 0 0" quat="0.5 0.5 -0.5 -0.5" type="mesh" mesh="link_1"/>
    <body name="link_0" pos="0.352977 0.721368 0.32133" quat="0.5 0.5 -0.5 -0.5">
      <inertial pos="0 0 0" mass="10" diaginertia="1 1 1"/>
      <joint name="joint_0" pos="0 0 0" axis="-1 0 0" range="0 3.14159" actuatorfrcrange="-100 100"/>
      <geom name="link_0_collision" pos="0.72 -0.32 0.35" quat="1 0 0 0" type="mesh" mesh="link_0"/>
    </body>
  </worldbody>
</mujoco>
