<robot name="partnet_985eb4a8f9914873738e43095496b061">
	<link name="base"><inertial><mass value="10"/><inertia ixx="1" ixy="0" ixz="0" iyy="1" iyz="0" izz="1"/></inertial></link>
	<link name="link_0">
		<inertial><mass value="10"/><inertia ixx="1" ixy="0" ixz="0" iyy="1" iyz="0" izz="1"/></inertial><collision name="link_0_collision"><origin xyz="0.72 -0.32 0.35"/><geometry><mesh filename="blender_meshes/link_0.obj"/></geometry></collision></link>
	<joint name="joint_0" type="revolute">
		<origin xyz="-0.7213680148124694 0.3213303004531701 -0.3529772990072755"/>
		<axis xyz="-1 0 0"/>
		<child link="link_0"/>
		<parent link="link_1"/>
		<limit lower="0.0" upper="3.141592653589793" effort="100" velocity="100"/>
	</joint>
	<link name="link_1">
		<inertial><mass value="10"/><inertia ixx="1" ixy="0" ixz="0" iyy="1" iyz="0" izz="1"/></inertial><collision name="link_1_collision"><origin xyz="0.00 0.00 0.00"/><geometry><mesh filename="blender_meshes/link_1.obj"/></geometry></collision></link>
	<joint name="joint_1" type="fixed">
		<origin rpy="1.570796326794897 0 -1.570796326794897" xyz="0 0 0"/>
		<child link="link_1"/>
		<parent link="base"/>
	<limit effort="100" velocity="100"/></joint>
<mujoco><compiler discardvisual="false" meshdir="blender_meshes"/></mujoco></robot>
